Workbook

Sheet Notas e Inst. de la Versión
A5: PCI DSS v4.0 - Herramienta de Enfoque Prioritario r1
A6: Notas e Instrucciones de la Versión
A7: Febrero de 2023
A9: Contenidos: 4 hojas de cálculo (ver fichas al final de esta página)
A10: · Notas e Instrucciones de la Versión (esta tabla)
A11: · Resumen de los Cambios
A12: · Hitos del Enfoque Prioritario
A13: · Resumen del Enfoque Prioritario
A15: Propósito: Herramienta para el seguimiento del progreso hacia la conformidad de PCI DSS versión 4.0 mediante el uso del Enfoque Prioritario. También se proporciona una herramienta de clasificación para analizar el progreso por requisito PCI DSS, categoría de hito o estado de hito.
A16: Paso 1: Indique "Sí", "No" o "N/A" en la columna C de la pestaña de la hoja de cálculo "Hitos del Enfoque Prioritario". Este paso completará automáticamente los campos de "porcentaje completo" en la pestaña de la hoja de cálculo "Resumen del Enfoque Prioritario".
A17: Sí | B17: Todos los elementos del requisito se han cumplido.
A18: No | B18: Algunos o todos los elementos del requisito no se han cumplido, o están en proceso de ser implementados, o requieren más pruebas antes de que el comerciante pueda confirmar que han sido implementados.
A19: N/A | B19: El requisito no aplica para el entorno de la entidad. Por ejemplo, un comerciante utilizaría N/A para aquellos requisitos que sólo se aplican si la entidad evaluada es un proveedor de servicios.
A20: Requisitos con Fecha Futura: No se requiere que estos nuevos requisitos se incluyan en una evaluación PCI DSS hasta que haya pasado la fecha futura. Antes de esa fecha futura, cualquier requisito nuevo con una fecha de implementación extendida que la entidad no haya implementado puede marcarse como N/A.
A21: Paso 2: Análisis de resultados. Utilice las funciones de "filtro" en los encabezados de las columnas de la pestaña de la hoja de cálculo "Hitos del Enfoque Prioritario" para seleccionar cualquiera de los seis hitos.
A22: Paso 3: Complete la Información de la Organización en la pestaña "Resumen del Enfoque Prioritario". Puede compartir este documento con su adquirente o con un evaluador de seguridad cualificado para que le proporcione una evaluación del progreso que su organización ha completado para lograr la conformidad de PCI DSS. También puede introducir manualmente una fecha estimada de finalización para cada fase de los hitos. Verifique con su adquirente las instrucciones específicas de presentación.
A23: Paso 4: Cuando consiga alcanzar el 100% de todos los requisitos enumerados en la categoría de hitos, hable con su adquirente o con las marcas de pago sobre los siguientes pasos. Las preguntas sobre el uso del Enfoque Prioritario y cómo el uso del Enfoque Prioritario puede afectar a las obligaciones de conformidad de una organización deben dirigirse a su adquirente o a las marcas de pago a las que su organización informa de la conformidad.
A24: Declaraciones: Este documento no modifica ni reduce a PCI DSS ni a ninguno de sus requisitos y puede ser modificado sin previo aviso. PCI SSC no se hace responsable de los errores o daños de cualquier tipo resultantes del uso de la información aquí contenida. PCI SSC no ofrece ninguna garantía o representación en relación con la información proporcionada en este documento y no asume ninguna responsabilidad en relación con el uso o el mal uso de dicha información.

Sheet Resumen de los Cambios
A7: PCI DSS v4.0 - Herramienta de Enfoque Prioritario r1
A8: Resumen de los Cambios
A9: Febrero de 2023
A11: Cambios en los Documentos
A13: Fecha | C13: Revisión | F13: Descripción
A14: Agosto de 2022 | C14: Herramienta de Enfoque Prioritario PCI DSS v4.0 | F14: Versión inicial para PCI DSS v4.0
A15: Febrero de 2023 | C15: PCI DSS v4.0 - Herramienta de Enfoque Prioritario r1 | F15: Las actualizaciones incluyen: - Inclusión de una pestaña de Resumen de Cambios - Explicación de las opciones de respuesta "Sí", "No" y "N/A", y cómo responder a los nuevos requisitos de PCI DSS v4.0 que no se requieren hasta el 31 de marzo de 2025 - Alineación de título y versión PCI DSS - Corrección de fórmula de hoja de cálculo - Actualizaciones a celdas editables

Sheet Resumen del Enfoque Prioritario
B5: Resumen del Enfoque Prioritario y Reconocimiento
B7: Parte 1: Información de Contacto
B8: Nombre de la Compañía | E8: Dirección Postal de la Compañía
B9: DBA (Actuando Comercialmente Como) | E9: Página Web Principal de la Compañía
B10: Nombre del Contacto de la Compañía
B11: Título del Contacto de la Compañía
B12: Número de Teléfono de Contacto
B13: Dirección de Correo Electrónico del Contacto
B15: Parte 2a: Canales de Pago Comerciales (Seleccione todos los que correspondan) | E15: Parte 2b: Empresa Proveedora de Servicios (Seleccione todo lo que corresponda)
B16: Pedido por correo/teléfono (MOTO) | E16: Proveedor de Alojamiento: | F16: Servicios Administrados: | G16: Procesamiento de Pagos:
B17: Comercio Electrónico | E17: Aplicaciones / software | F17: Servicios de seguridad del sistemas | G17: POI / tarjeta presencial
B18: Tarjeta presencial | E18: Hardware | F18: Apoyo TI | G18: Internet - comercio electrónico
B19: Otros procesamientos (especifique): | E19: Infraestructura / Red | F19: Seguridad Física | G19: MOTO / Centro de Llamadas
E20: Espacio físico (co-ubicación) | F20: Sistema de Gestión de Terminal | G20: ATM
B21: Parte 3: Relaciones | E21: Almacenamiento | F21: Otros servicios (especifique): | G21: Otros procesamientos (especifique):
B22: ¿Tiene su organización relación con uno o más agentes de terceros? | E22: Servicios de alojamiento Web
B23: (Por ejemplo: pasarelas, empresas de alojamiento web, agentes de reservas de aerolíneas, | E23: Servicios de seguridad
B24: agentes de programas de fidelización, etc) | E24: Proveedor de Hospedaje Seguro 3-D
E25: Proveedor de Servicios Multi-Usuario
E26: Otro tipo de Hospedaje (especifique):
B27: ¿Tiene su organización una relación con mas de un adquiriente?
E28: Gestión de Cuentas | F28: Fraude y Devoluciones | G28: Pasarela de Pagos/Conmutador
E29: Servicios Administrativos | F29: Procesamiento de Emisor | G29: Servicios Prepago
E30: Gestión de Facturación | F30: Programas de Lealtad | G30: Gestión de Registros
E31: Compensación y Liquidación | F31: Servicios Comerciales | G31: Pagos de Impuestos/Gobierno
E32: Proveedor de Red
E33: Otros (especifique):
B34: Parte 4: Procesamiento de Transacciones
B35: Aplicaciones de Pago en uso | E35: Enumere las instalaciones y ubicaciones incluidas en la Evaluación PCI DSS:
B36: Versión de la Aplicación de Pago
B49: Resumen del Enfoque Prioritario y Reconocimiento
B51: Hito | C51: Objetivos | F51: Porcentaje Completo | G51: Fecha Estimada de Finalización por Hito
B52: 1 | C52: No almacenar datos confidenciales de autenticación y limitar la retención de datos de tarjetahabientes. Este hito se dirige a un área clave de riesgo para las entidades que se han visto comprometidas. Recuerde: si no se almacenan datos confidenciales de autenticación y otros datos de tarjetahabientes los efectos de un compromiso se reducirán en gran medida. Si no lo necesita, no lo almacene. | F52: =IFERROR((Calcs!A341)/(COUNTIF('Hitos del Enfoque Prioritario'!B5:B341,"1")-(Calcs!H341)),1) -> 0 | G52: =IF(Calcs!AB341>0,"Falta la Fecha de Finalización",(IF(MAX(Calcs!P4:P341)=0,"",MAX(Calcs!P4:P341))))
B53: 2 | C53: Proteja los sistemas y las redes y esté preparado para responder a una infracción del sistema. Este hito tiene como objetivo los controles de los puntos de acceso a la mayoría de los compromisos y a los procesos de respuesta. | F53: =IFERROR((Calcs!B341)/(COUNTIF('Hitos del Enfoque Prioritario'!B5:B341,"2")-(Calcs!I341)),1) -> 0 | G53: =IF(Calcs!AC341>0,"Falta la Fecha de Finalización",(IF(MAX(Calcs!Q4:Q341)=0,"",MAX(Calcs!Q4:Q341))))
B54: 3 | C54: Aplicaciones de pago seguras. Este hito se dirige a los controles de las aplicaciones, los procesos de aplicación y los servidores de aplicaciones. Los puntos débiles en estas áreas son presa fácil para comprometer los sistemas y obtener acceso a los datos de tarjetahabientes. | F54: =IFERROR((Calcs!C341)/(COUNTIF('Hitos del Enfoque Prioritario'!B5:B341,"3")-(Calcs!J341)),1) -> 0 | G54: =IF(Calcs!AD341>0,"Falta la Fecha de Finalización",(IF(MAX(Calcs!R4:R341)=0,"",MAX(Calcs!R4:R341))))
B55: 4 | C55: Supervise y controle el acceso a sus sistemas. Los controles de este hito le permiten detectar el quién, el qué, el cuándo y el cómo en relación con el acceso a su red y al entorno de datos de tarjetahabientes. | F55: =IFERROR((Calcs!D341)/(COUNTIF('Hitos del Enfoque Prioritario'!B5:B341,"4")-(Calcs!K341)),1) -> 0 | G55: =IF(Calcs!AE341>0,"Falta la Fecha de Finalización",(IF(MAX(Calcs!S4:S341)=0,"",MAX(Calcs!S4:S341))))
B56: 5 | C56: Proteger los datos de tarjetahabientes almacenados. Para aquellas organizaciones que han analizado sus procesos de negocio y han determinado que deben almacenar Números de Cuenta Primarios, este hito se centra en los mecanismos de protección clave para los datos almacenados. | F56: =IFERROR((Calcs!E341)/(COUNTIF('Hitos del Enfoque Prioritario'!B5:B341,"5")-(Calcs!L341)),1) -> 0 | G56: =IF(Calcs!AF341>0,"Falta la Fecha de Finalización",(IF(MAX(Calcs!T4:T341)=0,"",MAX(Calcs!T4:T341))))
B57: 6 | C57: Finalice los esfuerzos de conformidad restantes y asegúrese de que todos los controles están implementados. Este hito completa los requisitos PCI DSS y finaliza todas las políticas, procedimientos y procesos relacionados restantes necesarios para proteger el entorno de datos de tarjetahabientes. | F57: =IFERROR((Calcs!F341)/(COUNTIF('Hitos del Enfoque Prioritario'!B5:B341,"6")-(Calcs!M341)),1) -> 0 | G57: =IF(Calcs!AG341>0,"Falta la Fecha de Finalización",(IF(MAX(Calcs!U4:U341)=0,"",MAX(Calcs!U4:U341))))
B58: General | F58: =Calcs!G341/(COUNT('Hitos del Enfoque Prioritario'!B5:B341)-Calcs!N341) -> 0 | G58: =IF(MAX(F52:F57)=0,"",MAX(G52:G57))
B60: A la organización que presente este formulario se le puede exigir que complete un Plan de Acción, que se encuentra en cada Certificado de Conformidad en la Parte 4: Plan de Acción para los Requisitos que se encuentran en situación de No Conformidad. Consulte con su entidad adquirente o con la(s) marca(s) de pago, ya que no todas las marcas de pago requieren completar un Plan de Acción.
...

Sheet Hitos del Enfoque Prioritario
A1: Requisitos PCI DSS v4.0 | B1: Hito | C1: Estado Por favor, introduzca "sí" si está totalmente en conformidad con el requisito | D1: Si el estado es "N/A", explique por qué el requisito No es Aplicable | E1: Si el estado es "No", complete lo siguiente
E2: Etapa de Implementación | F2: Fecha Estimada de Finalización por Hito | G2: Comentarios
A3: Requisito 1: Instalar y Mantener los Controles de Seguridad de la Red
A4: 1.1 Se definen y comprenden los procesos y mecanismos para instalar y mantener los controles de seguridad de la red.
A5: 1.1.1 Todas las políticas de seguridad y procedimientos operativos que se identifican en el Requisito 1 son: • Documentados. • Actualizados. • En uso. • Conocidos por todas las partes involucradas. | B5: 6
A6: 1.1.2 Los roles y responsabilidades para realizar las actividades del Requisito 1 están documentados, asignados y comprendidos. | B6: 6
A7: 1.2 Se configuran y mantienen los controles de seguridad de la red (NSC).
A8: 1.2.1 Los estándares de configuración para el conjunto de reglas de los NSC son: • Definidos. • Implementados. • Mantenido. | B8: 2
A9: 1.2.2 Todos los cambios en las conexiones de red y en las configuraciones de los NSC se aprueban y gestionan de acuerdo con el proceso de control de cambios definido en el Requisito 6.5.1. Notas de Aplicabilidad Los cambios en las conexiones de red incluyen la adición, eliminación o modificación de una conexión. Los cambios en las configuraciones del NSC incluyen aquellos relacionados con el propio componente, así como los que afectan la forma en que realiza su función de seguridad. | B9: 6
A10: 1.2.3 Se mantiene un diagrama de red precisos que muestra todas las conexiones entre el CDE y otras redes, incluyendo las redes inalámbricas. Notas de Aplicabilidad Se puede utilizar un(os) diagrama(s) de red vigente(s) u otra solución técnica o topológica que identifique las conexiones y dispositivos en la red para cumplir con este requisito. | B10: 1
A11: 1.2.4 Se mantienen diagramas de flujo de datos precisos que cumplen con lo siguiente: • Muestran todos los flujos de datos de tarjetahabientes a través de sistemas y redes. • Se actualizan según sea necesario ante cambios en el entorno. Notas de Aplicabilidad Se puede utilizar un diagrama de flujo de datos u otra solución técnica o topológica que identifique los flujos de datos de tarjetahabientes a través de sistemas y redes para cumplir con este requisito. | B11: 1
A12: 1.2.5 Todos los servicios, protocolos y puertos permitidos están identificados, aprobados y tienen una necesidad de negocio definida. | B12: 2
A13: 1.2.6 Las configuraciones de seguridad son definidas e implementadas para todos los servicios, protocolos y puertos que están en uso y que son considerados inseguros, de tal manera que el riesgo es mitigado. | B13: 2
A14: 1.2.7 Las configuraciones de los NSC se revisan al menos una vez cada seis meses para confirmar que son relevantes y eficientes. | B14: 6
A15: 1.2.8 Los archivos de configuración de los NSC están: • Asegurados contra el acceso no autorizado. • Se mantienen consistentes con las configuraciones de red activas. Notas de Aplicabilidad Cualquier archivo o ajuste utilizado para configurar o sincronizar los NSC se considera un “archivo de configuración.” Esto incluye archivos, controles automatizados y basados en el sistema, scripts, configuraciones, infraestructura como código u otros parámetros de los que se hace una copia de seguridad, se archivan o se almacenan de forma remota. | B15: 2
A16: 1.3 El acceso a la red hacia y desde el entorno de datos de tarjetahabientes está restringido.
A17: 1.3.1 El tráfico de entrada al CDE está restringido de la siguiente manera: • Sólo el tráfico que sea necesario, • Todo el resto del tráfico está específicamente denegado. | B17: 2
A18: 1.3.2 El tráfico saliente del CDE se restringe de la siguiente manera: • Sólo al tráfico necesario. • Todo el resto del tráfico está específicamente denegado. | B18: 2
A19: 1.3.3 Los NSC se implementan entre todas las redes inalámbricas y el CDE; esto es independientemente de que la red inalámbrica sea parte CDE o no, de manera que: • Todo el tráfico inalámbrico de las redes inalámbricas hacia el CDE es denegado de forma explícita. • Sólo se permite el tráfico inalámbrico al CDE que tenga un propósito de negocio autorizado. | B19: 2
A20: 1.4 Se controlan las conexiones de red entre las redes fiables y las que no lo son.
A21: 1.4.1 Los NSC se implementan entre redes confiables y no confiables. | B21: 2
A22: 1.4.2 El tráfico entrante de redes que no son confiables a redes confiables está restringido a: • Las comunicaciones con componentes del sistema autorizados para proveer servicios de acceso público, protocolos y puertos. • Respuestas las comunicaciones previamente iniciadas por componentes del sistema en una red confiable, esto para protocolos con dicho comportamiento. • Todo el tráfico restante está denegado. Notas de Aplicabilidad La intención de este requisito es abordar las sesiones de comunicación entre redes fiables y no fiables, en lugar de las especificaciones de los protocolos. Este requisito no limita el uso de UDP u otros protocolos de red no orientados a conexión si el comportamiento estándar del estado de la conexión del protocolo es mantenido y bajo el control del NSC. | B22: 2
A23: 1.4.3 Se implementan medidas Antispoofing para detectar y bloquear la entrada a la red confiable de direcciones IP origen falsas o suplantadas. | B23: 2
A24: 1.4.4 Los componentes del sistema que almacenan datos de tarjetahabientes no son accesibles directamente desde redes no confiables. Notas de Aplicabilidad Este requisito no se aplica al almacenamiento de datos de tarjetahabientes en memoria volátil, pero sí se aplica cuando la memoria se trata como almacenamiento persistente (por ejemplo, disco RAM). Los datos de tarjetahabientes sólo pueden almacenarse en la memoria volátil durante el tiempo necesario para apoyar el proceso de negocio asociado (por ejemplo, hasta la finalización transacción relacionada con tarjeta de pago). | B24: 2
A25: 1.4.5 La divulgación de las direcciones IP internas y la información de enrutamiento se limita sólo a las partes autorizadas. | B25: 2
A26: 1.5 Se mitigan los riesgos para el CDE desde dispositivos informáticos que pueden conectarse tanto a redes no confiables como al CDE.
A27: 1.5.1 Los controles de seguridad se implementan en cualquier dispositivo informático, incluyendo los dispositivos propiedad de la empresa y de los empleados, que se conectan tanto a redes no confiables (incluida Internet) como al CDE manera siguiente. • Se definen los parámetros de configuración específicos para impedir que se introduzcan amenazas en la red de la entidad. • Los controles de seguridad se están ejecutando activamente. • Los usuarios de los dispositivos informáticos no pueden alterar los controles de seguridad a menos que estén específicamente documentados y autorizados por el nivel gerencial, caso por caso, durante un período limitado. Notas de Aplicabilidad Estos controles de seguridad pueden desactivarse temporalmente solo si existe una necesidad técnica legítima, según lo autorizado por el nivel gerencial caso por caso. Se requiere de una autorización formal para desactivar estos controles de seguridad para y bajo un propósito específico. También puede ser necesario implementar medidas de seguridad adicionales durante el período durante el cual los controles de seguridad estén desactivados. Este requisito aplica a los dispositivos informáticos que sean propiedad tanto de la compañía como de los empleados. Los sistemas que no pueden ser administrados por políticas corporativas introducen debilidades y brindan oportunidades para que personas malintencionadas pueden explotarlas y/o aprovecharlas. | B27: 2
A28: Requisito 2: Aplicar Configuraciones Seguras a Todos los Componentes del Sistema
A29: 2.1 Se definen y comprenden los procesos y mecanismos para aplicar configuraciones seguras a todos los componentes del sistema.
A30: 2.1.1Todas las políticas de seguridad y procedimientos operativos que se identifican en el Requisito 2 están: • Documentados. • Actualizados. • En uso. • Conocidos por todas las partes involucradas. | B30: 6
A31: 2.1.2 Los roles y responsabilidades para realizar las actividades del Requisito 2 están documentados, asignados y comprendidos. Nuevo requisito - efectivo inmediatamente | B31: 6
A32: 2.2 Los componentes del sistema se configuran y administran de forma segura.
A33: 2.2.1 Las estándares de configuración se desarrollan, implementan y mantienen para: • Cubrir todos los componentes del sistema. • Cubrir todas las vulnerabilidades de seguridad conocidas. • Brindar coherencia con los estándares de hardening del sistema aceptados por el sector o con las recomendaciones de hardening del proveedor. • Ser actualizadas a medida que se identifican nuevos problemas de vulnerabilidad, como se define en el Requisito 6.3.1. • Ser aplicadas cuando los nuevos sistemas sean configurados y verificadas como establecidas antes o inmediatamente después de que un componente del sistema se conecte a un entorno de producción. | B33: 2
A34: 2.2.2 Las cuentas predeterminadas del proveedor se gestionan de la siguiente manera: • Si se utilizan las cuentas predeterminadas del proveedor, la contraseña predeterminada se cambia según el Requisito 8.3.6. • Si no se van a utilizar las cuentas predeterminadas del proveedor, la cuenta se elimina o se desactiva. Notas de Aplicabilidad Esto se aplica a TODAS las cuentas y contraseñas predeterminadas del proveedor, incluidas, entre otras, las utilizadas por los sistemas operativos, el software que proporciona servicios de seguridad, las cuentas de aplicaciones y sistemas, los terminales de punto de venta (POS), las aplicaciones de pago y los valores predeterminadas del Simple Network Management Protocol (SNMP). Este requisito también se aplica cuando un componente del sistema no está instalado en el entorno de una entidad, por ejemplo, el software y las aplicaciones que forman parte del CDE y a las que se ingresa a través de un servicio de suscripción en la nube. | B34: 2
A35: 2.2.3 Las funciones principales que requieren distintos niveles de seguridad se manejan como sigue: • Solo existe una función principal en un componente del sistema, O • Las funciones principales con distintos niveles de seguridad que existen en el mismo componente del sistema están aisladas entre sí, O • Las funciones primarias con distintos niveles de seguridad en el mismo componente del sistema están todas aseguradas al nivel requerido por la función que requiera un nivel mayor de seguridad. | B35: 2
A36: 2.2.4 Sólo se habilitan los servicios, protocolos, «demonios» y funciones necesarias, y se eliminan o deshabilitan todas las funciones innecesarias. | B36: 2
A37: 2.2.5 Si existen servicios, protocolos o «demonios» inseguros: • La justificación de negocio está documentada. • Se documentan e implementan características de seguridad adicionales que reducen el riesgo de utilizar servicios, protocolos o «demonios» inseguros. | B37: 2
A38: 2.2.6 Los parámetros de seguridad del sistema están configurados para impedir su uso indebido. | B38: 2
A39: 2.2.7 Todo el acceso administrativo sin consola está cifrado utilizando criptografía robusta. Notas de Aplicabilidad Esto incluye el acceso administrativo a través de interfaces basadas en navegador e interfaces de programación de aplicaciones (API). | B39: 2
A40: 2.3 Los entornos inalámbricos se configuran y administran de forma segura.
...

Sheet Calcs
A1: 1 | B1: 2 | C1: 3 | D1: 4 | E1: 5 | F1: 6 | G1: Total | H1: 1 - n/a | I1: 2 - n/a | J1: 3 - n/a | K1: 4 - n/a | L1: 5 - n/a | M1: 6 - n/a | N1: Total | P1: Date Value Detector re: Milestone 1 | Q1: Date Value Detector re: Milestone 2 | R1: Date Value Detector re: Milestone 3 | S1: Date Value Detector re: Milestone 4 | T1: Date Value Detector re: Milestone 5 | U1: Date Value Detector re: Milestone 6
P2: Milestone 1 Outstanding | Q2: Milestone 2 Outstanding | R2: Milestone 3 Outstanding | S2: Milestone 4 Outstanding | T2: Milestone 5 Outstanding | U2: Milestone 6 Outstanding | V2: Input Error Checker - "Yes" but still a date - Milestone 1 | W2: Input Error Checker - "Yes" but still a date - Milestone 2 | X2: Input Error Checker - "Yes" but still a date - Milestone 3 | Y2: Input Error Checker - "Yes" but still a date - Milestone 4 | Z2: Input Error Checker - "Yes" but still a date - Milestone 5 | AA2: Input Error Checker - "Yes" but still a date - Milestone 6 | AB2: Input Error Checker - "No" but no date - Milestone 1 | AC2: Input Error Checker - "No" but no date - Milestone 2 | AD2: Input Error Checker - "No" but no date - Milestone 3 | AE2: Input Error Checker - "No" but no date - Milestone 4 | AF2: Input Error Checker - "No" but no date - Milestone 5 | AG2: Input Error Checker - "No" but no date - Milestone 6
A4: =COUNTIFS('Hitos del Enfoque Prioritario'!B5,"1",'Hitos del Enfoque Prioritario'!C5,'Data Validation'!$A$2) -> 0 | B4: =COUNTIFS('Hitos del Enfoque Prioritario'!B5,"2",'Hitos del Enfoque Prioritario'!C5,'Data Validation'!$A$2) -> 0 | C4: =COUNTIFS('Hitos del Enfoque Prioritario'!B5,"3",'Hitos del Enfoque Prioritario'!C5,'Data Validation'!$A$2) -> 0 | D4: =COUNTIFS('Hitos del Enfoque Prioritario'!B5,"4",'Hitos del Enfoque Prioritario'!C5,'Data Validation'!$A$2) -> 0 | E4: =COUNTIFS('Hitos del Enfoque Prioritario'!B5,"5",'Hitos del Enfoque Prioritario'!C5,'Data Validation'!$A$2) -> 0 | F4: =COUNTIFS('Hitos del Enfoque Prioritario'!B5,"6",'Hitos del Enfoque Prioritario'!C5,'Data Validation'!$A$2) -> 0 | G4: =SUM(A4:F4) -> 0 | H4: =COUNTIFS('Hitos del Enfoque Prioritario'!B5,"1",'Hitos del Enfoque Prioritario'!C5,'Data Validation'!$A$4) -> 0 | I4: =COUNTIFS('Hitos del Enfoque Prioritario'!B5,"2",'Hitos del Enfoque Prioritario'!C5,'Data Validation'!$A$4) -> 0 | J4: =COUNTIFS('Hitos del Enfoque Prioritario'!B5,"3",'Hitos del Enfoque Prioritario'!C5,'Data Validation'!$A$4) -> 0 | K4: =COUNTIFS('Hitos del Enfoque Prioritario'!B5,"4",'Hitos del Enfoque Prioritario'!C5,'Data Validation'!$A$4) -> 0 | L4: =COUNTIFS('Hitos del Enfoque Prioritario'!B5,"5",'Hitos del Enfoque Prioritario'!C5,'Data Validation'!$A$4) -> 0 | M4: =COUNTIFS('Hitos del Enfoque Prioritario'!B5,"6",'Hitos del Enfoque Prioritario'!C5,'Data Validation'!$A$4) -> 0 | N4: =SUM(H4:M4) -> 0 | P4: =IF('Hitos del Enfoque Prioritario'!$B5=1,'Hitos del Enfoque Prioritario'!$F5,"") | Q4: =IF('Hitos del Enfoque Prioritario'!$B5=2,'Hitos del Enfoque Prioritario'!$F5,"") | R4: =IF('Hitos del Enfoque Prioritario'!$B5=3,'Hitos del Enfoque Prioritario'!$F5,"") | S4: =IF('Hitos del Enfoque Prioritario'!$B5=4,'Hitos del Enfoque Prioritario'!$F5,"") | T4: =IF('Hitos del Enfoque Prioritario'!$B5=5,'Hitos del Enfoque Prioritario'!$F5,"") | U4: =IF('Hitos del Enfoque Prioritario'!$B5=6,'Hitos del Enfoque Prioritario'!$F5,"") -> 0 | V4: =IF(AND('Hitos del Enfoque Prioritario'!C5='Data Validation'!$A$2,'Hitos del Enfoque Prioritario'!F5=""),"CORRECT",IF('Hitos del Enfoque Prioritario'!C5='Data Validation'!$A$3,"CORRECT",IF('Hitos del Enfoque Prioritario'!B5=1,"ERROR 1",'Data Validation'!$A$4))) -> N/A | W4: =IF(AND('Hitos del Enfoque Prioritario'!C5='Data Validation'!$A$2,'Hitos del Enfoque Prioritario'!F5=""),"CORRECT",IF('Hitos del Enfoque Prioritario'!C5='Data Validation'!$A$3,"CORRECT",IF('Hitos del Enfoque Prioritario'!B5=2,"ERROR 1",'Data Validation'!$A$4))) -> N/A | X4: =IF(AND('Hitos del Enfoque Prioritario'!C5='Data Validation'!$A$2,'Hitos del Enfoque Prioritario'!F5=""),"CORRECT",IF('Hitos del Enfoque Prioritario'!C5='Data Validation'!$A$3,"CORRECT",IF('Hitos del Enfoque Prioritario'!B5=3,"ERROR 1",'Data Validation'!$A$4))) -> N/A | Y4: =IF(AND('Hitos del Enfoque Prioritario'!C5='Data Validation'!$A$2,'Hitos del Enfoque Prioritario'!F5=""),"CORRECT",IF('Hitos del Enfoque Prioritario'!C5='Data Validation'!$A$3,"CORRECT",IF('Hitos del Enfoque Prioritario'!B5=4,"ERROR 1",'Data Validation'!$A$4))) -> N/A | Z4: =IF(AND('Hitos del Enfoque Prioritario'!C5='Data Validation'!$A$2,'Hitos del Enfoque Prioritario'!F5=""),"CORRECT",IF('Hitos del Enfoque Prioritario'!C5='Data Validation'!$A$3,"CORRECT",IF('Hitos del Enfoque Prioritario'!B5=5,"ERROR 1",'Data Validation'!$A$4))) -> N/A | AA4: =IF(AND('Hitos del Enfoque Prioritario'!C5='Data Validation'!$A$2,'Hitos del Enfoque Prioritario'!F5=""),"CORRECT",IF('Hitos del Enfoque Prioritario'!C5='Data Validation'!$A$3,"CORRECT",IF('Hitos del Enfoque Prioritario'!B5=6,"ERROR 1",'Data Validation'!$A$4))) -> ERROR 1 | AB4: =IF(AND('Hitos del Enfoque Prioritario'!C5='Data Validation'!$A$3,'Hitos del Enfoque Prioritario'!F5=""),IF('Hitos del Enfoque Prioritario'!B5=1,"ERROR 2",'Data Validation'!$A$4),"CORRECT") -> CORRECT | AC4: =IF(AND('Hitos del Enfoque Prioritario'!C5='Data Validation'!$A$3,'Hitos del Enfoque Prioritario'!F5=""),IF('Hitos del Enfoque Prioritario'!B5=2,"ERROR 2",'Data Validation'!$A$4),"CORRECT") -> CORRECT | AD4: =IF(AND('Hitos del Enfoque Prioritario'!C5='Data Validation'!$A$3,'Hitos del Enfoque Prioritario'!F5=""),IF('Hitos del Enfoque Prioritario'!B5=3,"ERROR 2",'Data Validation'!$A$4),"CORRECT") -> CORRECT | AE4: =IF(AND('Hitos del Enfoque Prioritario'!C5='Data Validation'!$A$3,'Hitos del Enfoque Prioritario'!F5=""),IF('Hitos del Enfoque Prioritario'!B5=4,"ERROR 2",'Data Validation'!$A$4),"CORRECT") -> CORRECT | AF4: =IF(AND('Hitos del Enfoque Prioritario'!C5='Data Validation'!$A$3,'Hitos del Enfoque Prioritario'!F5=""),IF('Hitos del Enfoque Prioritario'!B5=5,"ERROR 2",'Data Validation'!$A$4),"CORRECT") -> CORRECT | AG4: =IF(AND('Hitos del Enfoque Prioritario'!C5='Data Validation'!$A$3,'Hitos del Enfoque Prioritario'!F5=""),IF('Hitos del Enfoque Prioritario'!B5=6,"ERROR 2",'Data Validation'!$A$4),"CORRECT") -> CORRECT
A5: =COUNTIFS('Hitos del Enfoque Prioritario'!B6,"1",'Hitos del Enfoque Prioritario'!C6,'Data Validation'!$A$2) -> 0 | B5: =COUNTIFS('Hitos del Enfoque Prioritario'!B6,"2",'Hitos del Enfoque Prioritario'!C6,'Data Validation'!$A$2) -> 0 | C5: =COUNTIFS('Hitos del Enfoque Prioritario'!B6,"3",'Hitos del Enfoque Prioritario'!C6,'Data Validation'!$A$2) -> 0 | D5: =COUNTIFS('Hitos del Enfoque Prioritario'!B6,"4",'Hitos del Enfoque Prioritario'!C6,'Data Validation'!$A$2) -> 0 | E5: =COUNTIFS('Hitos del Enfoque Prioritario'!B6,"5",'Hitos del Enfoque Prioritario'!C6,'Data Validation'!$A$2) -> 0 | F5: =COUNTIFS('Hitos del Enfoque Prioritario'!B6,"6",'Hitos del Enfoque Prioritario'!C6,'Data Validation'!$A$2) -> 0 | G5: =SUM(A5:F5) -> 0 | H5: =COUNTIFS('Hitos del Enfoque Prioritario'!B6,"1",'Hitos del Enfoque Prioritario'!C6,'Data Validation'!$A$4) -> 0 | I5: =COUNTIFS('Hitos del Enfoque Prioritario'!B6,"2",'Hitos del Enfoque Prioritario'!C6,'Data Validation'!$A$4) -> 0 | J5: =COUNTIFS('Hitos del Enfoque Prioritario'!B6,"3",'Hitos del Enfoque Prioritario'!C6,'Data Validation'!$A$4) -> 0 | K5: =COUNTIFS('Hitos del Enfoque Prioritario'!B6,"4",'Hitos del Enfoque Prioritario'!C6,'Data Validation'!$A$4) -> 0 | L5: =COUNTIFS('Hitos del Enfoque Prioritario'!B6,"5",'Hitos del Enfoque Prioritario'!C6,'Data Validation'!$A$4) -> 0 | M5: =COUNTIFS('Hitos del Enfoque Prioritario'!B6,"6",'Hitos del Enfoque Prioritario'!C6,'Data Validation'!$A$4) -> 0 | N5: =SUM(H5:M5) -> 0 | P5: =IF('Hitos del Enfoque Prioritario'!$B6=1,'Hitos del Enfoque Prioritario'!$F6,"") | Q5: =IF('Hitos del Enfoque Prioritario'!$B6=2,'Hitos del Enfoque Prioritario'!$F6,"") | R5: =IF('Hitos del Enfoque Prioritario'!$B6=3,'Hitos del Enfoque Prioritario'!$F6,"") | S5: =IF('Hitos del Enfoque Prioritario'!$B6=4,'Hitos del Enfoque Prioritario'!$F6,"") | T5: =IF('Hitos del Enfoque Prioritario'!$B6=5,'Hitos del Enfoque Prioritario'!$F6,"") | U5: =IF('Hitos del Enfoque Prioritario'!$B6=6,'Hitos del Enfoque Prioritario'!$F6,"") -> 0 | V5: =IF(AND('Hitos del Enfoque Prioritario'!C6='Data Validation'!$A$2,'Hitos del Enfoque Prioritario'!F6=""),"CORRECT",IF('Hitos del Enfoque Prioritario'!C6='Data Validation'!$A$3,"CORRECT",IF('Hitos del Enfoque Prioritario'!B6=1,"ERROR 1",'Data Validation'!$A$4))) -> N/A | W5: =IF(AND('Hitos del Enfoque Prioritario'!C6='Data Validation'!$A$2,'Hitos del Enfoque Prioritario'!F6=""),"CORRECT",IF('Hitos del Enfoque Prioritario'!C6='Data Validation'!$A$3,"CORRECT",IF('Hitos del Enfoque Prioritario'!B6=2,"ERROR 1",'Data Validation'!$A$4))) -> N/A | X5: =IF(AND('Hitos del Enfoque Prioritario'!C6='Data Validation'!$A$2,'Hitos del Enfoque Prioritario'!F6=""),"CORRECT",IF('Hitos del Enfoque Prioritario'!C6='Data Validation'!$A$3,"CORRECT",IF('Hitos del Enfoque Prioritario'!B6=3,"ERROR 1",'Data Validation'!$A$4))) -> N/A | Y5: =IF(AND('Hitos del Enfoque Prioritario'!C6='Data Validation'!$A$2,'Hitos del Enfoque Prioritario'!F6=""),"CORRECT",IF('Hitos del Enfoque Prioritario'!C6='Data Validation'!$A$3,"CORRECT",IF('Hitos del Enfoque Prioritario'!B6=4,"ERROR 1",'Data Validation'!$A$4))) -> N/A | Z5: =IF(AND('Hitos del Enfoque Prioritario'!C6='Data Validation'!$A$2,'Hitos del Enfoque Prioritario'!F6=""),"CORRECT",IF('Hitos del Enfoque Prioritario'!C6='Data Validation'!$A$3,"CORRECT",IF('Hitos del Enfoque Prioritario'!B6=5,"ERROR 1",'Data Validation'!$A$4))) -> N/A | AA5: =IF(AND('Hitos del Enfoque Prioritario'!C6='Data Validation'!$A$2,'Hitos del Enfoque Prioritario'!F6=""),"CORRECT",IF('Hitos del Enfoque Prioritario'!C6='Data Validation'!$A$3,"CORRECT",IF('Hitos del Enfoque Prioritario'!B6=6,"ERROR 1",'Data Validation'!$A$4))) -> ERROR 1 | AB5: =IF(AND('Hitos del Enfoque Prioritario'!C6='Data Validation'!$A$3,'Hitos del Enfoque Prioritario'!F6=""),IF('Hitos del Enfoque Prioritario'!B6=1,"ERROR 2",'Data Validation'!$A$4),"CORRECT") -> CORRECT | AC5: =IF(AND('Hitos del Enfoque Prioritario'!C6='Data Validation'!$A$3,'Hitos del Enfoque Prioritario'!F6=""),IF('Hitos del Enfoque Prioritario'!B6=2,"ERROR 2",'Data Validation'!$A$4),"CORRECT") -> CORRECT | AD5: =IF(AND('Hitos del Enfoque Prioritario'!C6='Data Validation'!$A$3,'Hitos del Enfoque Prioritario'!F6=""),IF('Hitos del Enfoque Prioritario'!B6=3,"ERROR 2",'Data Validation'!$A$4),"CORRECT") -> CORRECT | AE5: =IF(AND('Hitos del Enfoque Prioritario'!C6='Data Validation'!$A$3,'Hitos del Enfoque Prioritario'!F6=""),IF('Hitos del Enfoque Prioritario'!B6=4,"ERROR 2",'Data Validation'!$A$4),"CORRECT") -> CORRECT | AF5: =IF(AND('Hitos del Enfoque Prioritario'!C6='Data Validation'!$A$3,'Hitos del Enfoque Prioritario'!F6=""),IF('Hitos del Enfoque Prioritario'!B6=5,"ERROR 2",'Data Validation'!$A$4),"CORRECT") -> CORRECT | AG5: =IF(AND('Hitos del Enfoque Prioritario'!C6='Data Validation'!$A$3,'Hitos del Enfoque Prioritario'!F6=""),IF('Hitos del Enfoque Prioritario'!B6=6,"ERROR 2",'Data Validation'!$A$4),"CORRECT") -> CORRECT
A6: =COUNTIFS('Hitos del Enfoque Prioritario'!B7,"1",'Hitos del Enfoque Prioritario'!C7,'Data Validation'!$A$2) -> 0 | B6: =COUNTIFS('Hitos del Enfoque Prioritario'!B7,"2",'Hitos del Enfoque Prioritario'!C7,'Data Validation'!$A$2) -> 0 | C6: =COUNTIFS('Hitos del Enfoque Prioritario'!B7,"3",'Hitos del Enfoque Prioritario'!C7,'Data Validation'!$A$2) -> 0 | D6: =COUNTIFS('Hitos del Enfoque Prioritario'!B7,"4",'Hitos del Enfoque Prioritario'!C7,'Data Validation'!$A$2) -> 0 | E6: =COUNTIFS('Hitos del Enfoque Prioritario'!B7,"5",'Hitos del Enfoque Prioritario'!C7,'Data Validation'!$A$2) -> 0 | F6: =COUNTIFS('Hitos del Enfoque Prioritario'!B7,"6",'Hitos del Enfoque Prioritario'!C7,'Data Validation'!$A$2) -> 0 | G6: =SUM(A6:F6) -> 0 | H6: =COUNTIFS('Hitos del Enfoque Prioritario'!B7,"1",'Hitos del Enfoque Prioritario'!C7,'Data Validation'!$A$4) -> 0 | I6: =COUNTIFS('Hitos del Enfoque Prioritario'!B7,"2",'Hitos del Enfoque Prioritario'!C7,'Data Validation'!$A$4) -> 0 | J6: =COUNTIFS('Hitos del Enfoque Prioritario'!B7,"3",'Hitos del Enfoque Prioritario'!C7,'Data Validation'!$A$4) -> 0 | K6: =COUNTIFS('Hitos del Enfoque Prioritario'!B7,"4",'Hitos del Enfoque Prioritario'!C7,'Data Validation'!$A$4) -> 0 | L6: =COUNTIFS('Hitos del Enfoque Prioritario'!B7,"5",'Hitos del Enfoque Prioritario'!C7,'Data Validation'!$A$4) -> 0 | M6: =COUNTIFS('Hitos del Enfoque Prioritario'!B7,"6",'Hitos del Enfoque Prioritario'!C7,'Data Validation'!$A$4) -> 0 | N6: =SUM(H6:M6) -> 0 | P6: =IF('Hitos del Enfoque Prioritario'!$B7=1,'Hitos del Enfoque Prioritario'!$F7,"") | Q6: =IF('Hitos del Enfoque Prioritario'!$B7=2,'Hitos del Enfoque Prioritario'!$F7,"") | R6: =IF('Hitos del Enfoque Prioritario'!$B7=3,'Hitos del Enfoque Prioritario'!$F7,"") | S6: =IF('Hitos del Enfoque Prioritario'!$B7=4,'Hitos del Enfoque Prioritario'!$F7,"") | T6: =IF('Hitos del Enfoque Prioritario'!$B7=5,'Hitos del Enfoque Prioritario'!$F7,"") | U6: =IF('Hitos del Enfoque Prioritario'!$B7=6,'Hitos del Enfoque Prioritario'!$F7,"") | V6: =IF(AND('Hitos del Enfoque Prioritario'!C7='Data Validation'!$A$2,'Hitos del Enfoque Prioritario'!F7=""),"CORRECT",IF('Hitos del Enfoque Prioritario'!C7='Data Validation'!$A$3,"CORRECT",IF('Hitos del Enfoque Prioritario'!B7=1,"ERROR 1",'Data Validation'!$A$4))) -> N/A | W6: =IF(AND('Hitos del Enfoque Prioritario'!C7='Data Validation'!$A$2,'Hitos del Enfoque Prioritario'!F7=""),"CORRECT",IF('Hitos del Enfoque Prioritario'!C7='Data Validation'!$A$3,"CORRECT",IF('Hitos del Enfoque Prioritario'!B7=2,"ERROR 1",'Data Validation'!$A$4))) -> N/A | X6: =IF(AND('Hitos del Enfoque Prioritario'!C7='Data Validation'!$A$2,'Hitos del Enfoque Prioritario'!F7=""),"CORRECT",IF('Hitos del Enfoque Prioritario'!C7='Data Validation'!$A$3,"CORRECT",IF('Hitos del Enfoque Prioritario'!B7=3,"ERROR 1",'Data Validation'!$A$4))) -> N/A | Y6: =IF(AND('Hitos del Enfoque Prioritario'!C7='Data Validation'!$A$2,'Hitos del Enfoque Prioritario'!F7=""),"CORRECT",IF('Hitos del Enfoque Prioritario'!C7='Data Validation'!$A$3,"CORRECT",IF('Hitos del Enfoque Prioritario'!B7=4,"ERROR 1",'Data Validation'!$A$4))) -> N/A | Z6: =IF(AND('Hitos del Enfoque Prioritario'!C7='Data Validation'!$A$2,'Hitos del Enfoque Prioritario'!F7=""),"CORRECT",IF('Hitos del Enfoque Prioritario'!C7='Data Validation'!$A$3,"CORRECT",IF('Hitos del Enfoque Prioritario'!B7=5,"ERROR 1",'Data Validation'!$A$4))) -> N/A | AA6: =IF(AND('Hitos del Enfoque Prioritario'!C7='Data Validation'!$A$2,'Hitos del Enfoque Prioritario'!F7=""),"CORRECT",IF('Hitos del Enfoque Prioritario'!C7='Data Validation'!$A$3,"CORRECT",IF('Hitos del Enfoque Prioritario'!B7=6,"ERROR 1",'Data Validation'!$A$4))) -> N/A | AB6: =IF(AND('Hitos del Enfoque Prioritario'!C7='Data Validation'!$A$3,'Hitos del Enfoque Prioritario'!F7=""),IF('Hitos del Enfoque Prioritario'!B7=1,"ERROR 2",'Data Validation'!$A$4),"CORRECT") -> CORRECT | AC6: =IF(AND('Hitos del Enfoque Prioritario'!C7='Data Validation'!$A$3,'Hitos del Enfoque Prioritario'!F7=""),IF('Hitos del Enfoque Prioritario'!B7=2,"ERROR 2",'Data Validation'!$A$4),"CORRECT") -> CORRECT | AD6: =IF(AND('Hitos del Enfoque Prioritario'!C7='Data Validation'!$A$3,'Hitos del Enfoque Prioritario'!F7=""),IF('Hitos del Enfoque Prioritario'!B7=3,"ERROR 2",'Data Validation'!$A$4),"CORRECT") -> CORRECT | AE6: =IF(AND('Hitos del Enfoque Prioritario'!C7='Data Validation'!$A$3,'Hitos del Enfoque Prioritario'!F7=""),IF('Hitos del Enfoque Prioritario'!B7=4,"ERROR 2",'Data Validation'!$A$4),"CORRECT") -> CORRECT | AF6: =IF(AND('Hitos del Enfoque Prioritario'!C7='Data Validation'!$A$3,'Hitos del Enfoque Prioritario'!F7=""),IF('Hitos del Enfoque Prioritario'!B7=5,"ERROR 2",'Data Validation'!$A$4),"CORRECT") -> CORRECT | AG6: =IF(AND('Hitos del Enfoque Prioritario'!C7='Data Validation'!$A$3,'Hitos del Enfoque Prioritario'!F7=""),IF('Hitos del Enfoque Prioritario'!B7=6,"ERROR 2",'Data Validation'!$A$4),"CORRECT") -> CORRECT
A7: =COUNTIFS('Hitos del Enfoque Prioritario'!B8,"1",'Hitos del Enfoque Prioritario'!C8,'Data Validation'!$A$2) -> 0 | B7: =COUNTIFS('Hitos del Enfoque Prioritario'!B8,"2",'Hitos del Enfoque Prioritario'!C8,'Data Validation'!$A$2) -> 0 | C7: =COUNTIFS('Hitos del Enfoque Prioritario'!B8,"3",'Hitos del Enfoque Prioritario'!C8,'Data Validation'!$A$2) -> 0 | D7: =COUNTIFS('Hitos del Enfoque Prioritario'!B8,"4",'Hitos del Enfoque Prioritario'!C8,'Data Validation'!$A$2) -> 0 | E7: =COUNTIFS('Hitos del Enfoque Prioritario'!B8,"5",'Hitos del Enfoque Prioritario'!C8,'Data Validation'!$A$2) -> 0 | F7: =COUNTIFS('Hitos del Enfoque Prioritario'!B8,"6",'Hitos del Enfoque Prioritario'!C8,'Data Validation'!$A$2) -> 0 | G7: =SUM(A7:F7) -> 0 | H7: =COUNTIFS('Hitos del Enfoque Prioritario'!B8,"1",'Hitos del Enfoque Prioritario'!C8,'Data Validation'!$A$4) -> 0 | I7: =COUNTIFS('Hitos del Enfoque Prioritario'!B8,"2",'Hitos del Enfoque Prioritario'!C8,'Data Validation'!$A$4) -> 0 | J7: =COUNTIFS('Hitos del Enfoque Prioritario'!B8,"3",'Hitos del Enfoque Prioritario'!C8,'Data Validation'!$A$4) -> 0 | K7: =COUNTIFS('Hitos del Enfoque Prioritario'!B8,"4",'Hitos del Enfoque Prioritario'!C8,'Data Validation'!$A$4) -> 0 | L7: =COUNTIFS('Hitos del Enfoque Prioritario'!B8,"5",'Hitos del Enfoque Prioritario'!C8,'Data Validation'!$A$4) -> 0 | M7: =COUNTIFS('Hitos del Enfoque Prioritario'!B8,"6",'Hitos del Enfoque Prioritario'!C8,'Data Validation'!$A$4) -> 0 | N7: =SUM(H7:M7) -> 0 | P7: =IF('Hitos del Enfoque Prioritario'!$B8=1,'Hitos del Enfoque Prioritario'!$F8,"") | Q7: =IF('Hitos del Enfoque Prioritario'!$B8=2,'Hitos del Enfoque Prioritario'!$F8,"") -> 0 | R7: =IF('Hitos del Enfoque Prioritario'!$B8=3,'Hitos del Enfoque Prioritario'!$F8,"") | S7: =IF('Hitos del Enfoque Prioritario'!$B8=4,'Hitos del Enfoque Prioritario'!$F8,"") | T7: =IF('Hitos del Enfoque Prioritario'!$B8=5,'Hitos del Enfoque Prioritario'!$F8,"") | U7: =IF('Hitos del Enfoque Prioritario'!$B8=6,'Hitos del Enfoque Prioritario'!$F8,"") | V7: =IF(AND('Hitos del Enfoque Prioritario'!C8='Data Validation'!$A$2,'Hitos del Enfoque Prioritario'!F8=""),"CORRECT",IF('Hitos del Enfoque Prioritario'!C8='Data Validation'!$A$3,"CORRECT",IF('Hitos del Enfoque Prioritario'!B8=1,"ERROR 1",'Data Validation'!$A$4))) -> N/A | W7: =IF(AND('Hitos del Enfoque Prioritario'!C8='Data Validation'!$A$2,'Hitos del Enfoque Prioritario'!F8=""),"CORRECT",IF('Hitos del Enfoque Prioritario'!C8='Data Validation'!$A$3,"CORRECT",IF('Hitos del Enfoque Prioritario'!B8=2,"ERROR 1",'Data Validation'!$A$4))) -> ERROR 1 | X7: =IF(AND('Hitos del Enfoque Prioritario'!C8='Data Validation'!$A$2,'Hitos del Enfoque Prioritario'!F8=""),"CORRECT",IF('Hitos del Enfoque Prioritario'!C8='Data Validation'!$A$3,"CORRECT",IF('Hitos del Enfoque Prioritario'!B8=3,"ERROR 1",'Data Validation'!$A$4))) -> N/A | Y7: =IF(AND('Hitos del Enfoque Prioritario'!C8='Data Validation'!$A$2,'Hitos del Enfoque Prioritario'!F8=""),"CORRECT",IF('Hitos del Enfoque Prioritario'!C8='Data Validation'!$A$3,"CORRECT",IF('Hitos del Enfoque Prioritario'!B8=4,"ERROR 1",'Data Validation'!$A$4))) -> N/A | Z7: =IF(AND('Hitos del Enfoque Prioritario'!C8='Data Validation'!$A$2,'Hitos del Enfoque Prioritario'!F8=""),"CORRECT",IF('Hitos del Enfoque Prioritario'!C8='Data Validation'!$A$3,"CORRECT",IF('Hitos del Enfoque Prioritario'!B8=5,"ERROR 1",'Data Validation'!$A$4))) -> N/A | AA7: =IF(AND('Hitos del Enfoque Prioritario'!C8='Data Validation'!$A$2,'Hitos del Enfoque Prioritario'!F8=""),"CORRECT",IF('Hitos del Enfoque Prioritario'!C8='Data Validation'!$A$3,"CORRECT",IF('Hitos del Enfoque Prioritario'!B8=6,"ERROR 1",'Data Validation'!$A$4))) -> N/A | AB7: =IF(AND('Hitos del Enfoque Prioritario'!C8='Data Validation'!$A$3,'Hitos del Enfoque Prioritario'!F8=""),IF('Hitos del Enfoque Prioritario'!B8=1,"ERROR 2",'Data Validation'!$A$4),"CORRECT") -> CORRECT | AC7: =IF(AND('Hitos del Enfoque Prioritario'!C8='Data Validation'!$A$3,'Hitos del Enfoque Prioritario'!F8=""),IF('Hitos del Enfoque Prioritario'!B8=2,"ERROR 2",'Data Validation'!$A$4),"CORRECT") -> CORRECT | AD7: =IF(AND('Hitos del Enfoque Prioritario'!C8='Data Validation'!$A$3,'Hitos del Enfoque Prioritario'!F8=""),IF('Hitos del Enfoque Prioritario'!B8=3,"ERROR 2",'Data Validation'!$A$4),"CORRECT") -> CORRECT | AE7: =IF(AND('Hitos del Enfoque Prioritario'!C8='Data Validation'!$A$3,'Hitos del Enfoque Prioritario'!F8=""),IF('Hitos del Enfoque Prioritario'!B8=4,"ERROR 2",'Data Validation'!$A$4),"CORRECT") -> CORRECT | AF7: =IF(AND('Hitos del Enfoque Prioritario'!C8='Data Validation'!$A$3,'Hitos del Enfoque Prioritario'!F8=""),IF('Hitos del Enfoque Prioritario'!B8=5,"ERROR 2",'Data Validation'!$A$4),"CORRECT") -> CORRECT | AG7: =IF(AND('Hitos del Enfoque Prioritario'!C8='Data Validation'!$A$3,'Hitos del Enfoque Prioritario'!F8=""),IF('Hitos del Enfoque Prioritario'!B8=6,"ERROR 2",'Data Validation'!$A$4),"CORRECT") -> CORRECT
A8: =COUNTIFS('Hitos del Enfoque Prioritario'!B9,"1",'Hitos del Enfoque Prioritario'!C9,'Data Validation'!$A$2) -> 0 | B8: =COUNTIFS('Hitos del Enfoque Prioritario'!B9,"2",'Hitos del Enfoque Prioritario'!C9,'Data Validation'!$A$2) -> 0 | C8: =COUNTIFS('Hitos del Enfoque Prioritario'!B9,"3",'Hitos del Enfoque Prioritario'!C9,'Data Validation'!$A$2) -> 0 | D8: =COUNTIFS('Hitos del Enfoque Prioritario'!B9,"4",'Hitos del Enfoque Prioritario'!C9,'Data Validation'!$A$2) -> 0 | E8: =COUNTIFS('Hitos del Enfoque Prioritario'!B9,"5",'Hitos del Enfoque Prioritario'!C9,'Data Validation'!$A$2) -> 0 | F8: =COUNTIFS('Hitos del Enfoque Prioritario'!B9,"6",'Hitos del Enfoque Prioritario'!C9,'Data Validation'!$A$2) -> 0 | G8: =SUM(A8:F8) -> 0 | H8: =COUNTIFS('Hitos del Enfoque Prioritario'!B9,"1",'Hitos del Enfoque Prioritario'!C9,'Data Validation'!$A$4) -> 0 | I8: =COUNTIFS('Hitos del Enfoque Prioritario'!B9,"2",'Hitos del Enfoque Prioritario'!C9,'Data Validation'!$A$4) -> 0 | J8: =COUNTIFS('Hitos del Enfoque Prioritario'!B9,"3",'Hitos del Enfoque Prioritario'!C9,'Data Validation'!$A$4) -> 0 | K8: =COUNTIFS('Hitos del Enfoque Prioritario'!B9,"4",'Hitos del Enfoque Prioritario'!C9,'Data Validation'!$A$4) -> 0 | L8: =COUNTIFS('Hitos del Enfoque Prioritario'!B9,"5",'Hitos del Enfoque Prioritario'!C9,'Data Validation'!$A$4) -> 0 | M8: =COUNTIFS('Hitos del Enfoque Prioritario'!B9,"6",'Hitos del Enfoque Prioritario'!C9,'Data Validation'!$A$4) -> 0 | N8: =SUM(H8:M8) -> 0 | P8: =IF('Hitos del Enfoque Prioritario'!$B9=1,'Hitos del Enfoque Prioritario'!$F9,"") | Q8: =IF('Hitos del Enfoque Prioritario'!$B9=2,'Hitos del Enfoque Prioritario'!$F9,"") | R8: =IF('Hitos del Enfoque Prioritario'!$B9=3,'Hitos del Enfoque Prioritario'!$F9,"") | S8: =IF('Hitos del Enfoque Prioritario'!$B9=4,'Hitos del Enfoque Prioritario'!$F9,"") | T8: =IF('Hitos del Enfoque Prioritario'!$B9=5,'Hitos del Enfoque Prioritario'!$F9,"") | U8: =IF('Hitos del Enfoque Prioritario'!$B9=6,'Hitos del Enfoque Prioritario'!$F9,"") -> 0 | V8: =IF(AND('Hitos del Enfoque Prioritario'!C9='Data Validation'!$A$2,'Hitos del Enfoque Prioritario'!F9=""),"CORRECT",IF('Hitos del Enfoque Prioritario'!C9='Data Validation'!$A$3,"CORRECT",IF('Hitos del Enfoque Prioritario'!B9=1,"ERROR 1",'Data Validation'!$A$4))) -> N/A | W8: =IF(AND('Hitos del Enfoque Prioritario'!C9='Data Validation'!$A$2,'Hitos del Enfoque Prioritario'!F9=""),"CORRECT",IF('Hitos del Enfoque Prioritario'!C9='Data Validation'!$A$3,"CORRECT",IF('Hitos del Enfoque Prioritario'!B9=2,"ERROR 1",'Data Validation'!$A$4))) -> N/A | X8: =IF(AND('Hitos del Enfoque Prioritario'!C9='Data Validation'!$A$2,'Hitos del Enfoque Prioritario'!F9=""),"CORRECT",IF('Hitos del Enfoque Prioritario'!C9='Data Validation'!$A$3,"CORRECT",IF('Hitos del Enfoque Prioritario'!B9=3,"ERROR 1",'Data Validation'!$A$4))) -> N/A | Y8: =IF(AND('Hitos del Enfoque Prioritario'!C9='Data Validation'!$A$2,'Hitos del Enfoque Prioritario'!F9=""),"CORRECT",IF('Hitos del Enfoque Prioritario'!C9='Data Validation'!$A$3,"CORRECT",IF('Hitos del Enfoque Prioritario'!B9=4,"ERROR 1",'Data Validation'!$A$4))) -> N/A | Z8: =IF(AND('Hitos del Enfoque Prioritario'!C9='Data Validation'!$A$2,'Hitos del Enfoque Prioritario'!F9=""),"CORRECT",IF('Hitos del Enfoque Prioritario'!C9='Data Validation'!$A$3,"CORRECT",IF('Hitos del Enfoque Prioritario'!B9=5,"ERROR 1",'Data Validation'!$A$4))) -> N/A | AA8: =IF(AND('Hitos del Enfoque Prioritario'!C9='Data Validation'!$A$2,'Hitos del Enfoque Prioritario'!F9=""),"CORRECT",IF('Hitos del Enfoque Prioritario'!C9='Data Validation'!$A$3,"CORRECT",IF('Hitos del Enfoque Prioritario'!B9=6,"ERROR 1",'Data Validation'!$A$4))) -> ERROR 1 | AB8: =IF(AND('Hitos del Enfoque Prioritario'!C9='Data Validation'!$A$3,'Hitos del Enfoque Prioritario'!F9=""),IF('Hitos del Enfoque Prioritario'!B9=1,"ERROR 2",'Data Validation'!$A$4),"CORRECT") -> CORRECT | AC8: =IF(AND('Hitos del Enfoque Prioritario'!C9='Data Validation'!$A$3,'Hitos del Enfoque Prioritario'!F9=""),IF('Hitos del Enfoque Prioritario'!B9=2,"ERROR 2",'Data Validation'!$A$4),"CORRECT") -> CORRECT | AD8: =IF(AND('Hitos del Enfoque Prioritario'!C9='Data Validation'!$A$3,'Hitos del Enfoque Prioritario'!F9=""),IF('Hitos del Enfoque Prioritario'!B9=3,"ERROR 2",'Data Validation'!$A$4),"CORRECT") -> CORRECT | AE8: =IF(AND('Hitos del Enfoque Prioritario'!C9='Data Validation'!$A$3,'Hitos del Enfoque Prioritario'!F9=""),IF('Hitos del Enfoque Prioritario'!B9=4,"ERROR 2",'Data Validation'!$A$4),"CORRECT") -> CORRECT | AF8: =IF(AND('Hitos del Enfoque Prioritario'!C9='Data Validation'!$A$3,'Hitos del Enfoque Prioritario'!F9=""),IF('Hitos del Enfoque Prioritario'!B9=5,"ERROR 2",'Data Validation'!$A$4),"CORRECT") -> CORRECT | AG8: =IF(AND('Hitos del Enfoque Prioritario'!C9='Data Validation'!$A$3,'Hitos del Enfoque Prioritario'!F9=""),IF('Hitos del Enfoque Prioritario'!B9=6,"ERROR 2",'Data Validation'!$A$4),"CORRECT") -> CORRECT
A9: =COUNTIFS('Hitos del Enfoque Prioritario'!B10,"1",'Hitos del Enfoque Prioritario'!C10,'Data Validation'!$A$2) -> 0 | B9: =COUNTIFS('Hitos del Enfoque Prioritario'!B10,"2",'Hitos del Enfoque Prioritario'!C10,'Data Validation'!$A$2) -> 0 | C9: =COUNTIFS('Hitos del Enfoque Prioritario'!B10,"3",'Hitos del Enfoque Prioritario'!C10,'Data Validation'!$A$2) -> 0 | D9: =COUNTIFS('Hitos del Enfoque Prioritario'!B10,"4",'Hitos del Enfoque Prioritario'!C10,'Data Validation'!$A$2) -> 0 | E9: =COUNTIFS('Hitos del Enfoque Prioritario'!B10,"5",'Hitos del Enfoque Prioritario'!C10,'Data Validation'!$A$2) -> 0 | F9: =COUNTIFS('Hitos del Enfoque Prioritario'!B10,"6",'Hitos del Enfoque Prioritario'!C10,'Data Validation'!$A$2) -> 0 | G9: =SUM(A9:F9) -> 0 | H9: =COUNTIFS('Hitos del Enfoque Prioritario'!B10,"1",'Hitos del Enfoque Prioritario'!C10,'Data Validation'!$A$4) -> 0 | I9: =COUNTIFS('Hitos del Enfoque Prioritario'!B10,"2",'Hitos del Enfoque Prioritario'!C10,'Data Validation'!$A$4) -> 0 | J9: =COUNTIFS('Hitos del Enfoque Prioritario'!B10,"3",'Hitos del Enfoque Prioritario'!C10,'Data Validation'!$A$4) -> 0 | K9: =COUNTIFS('Hitos del Enfoque Prioritario'!B10,"4",'Hitos del Enfoque Prioritario'!C10,'Data Validation'!$A$4) -> 0 | L9: =COUNTIFS('Hitos del Enfoque Prioritario'!B10,"5",'Hitos del Enfoque Prioritario'!C10,'Data Validation'!$A$4) -> 0 | M9: =COUNTIFS('Hitos del Enfoque Prioritario'!B10,"6",'Hitos del Enfoque Prioritario'!C10,'Data Validation'!$A$4) -> 0 | N9: =SUM(H9:M9) -> 0 | P9: =IF('Hitos del Enfoque Prioritario'!$B10=1,'Hitos del Enfoque Prioritario'!$F10,"") -> 0 | Q9: =IF('Hitos del Enfoque Prioritario'!$B10=2,'Hitos del Enfoque Prioritario'!$F10,"") | R9: =IF('Hitos del Enfoque Prioritario'!$B10=3,'Hitos del Enfoque Prioritario'!$F10,"") | S9: =IF('Hitos del Enfoque Prioritario'!$B10=4,'Hitos del Enfoque Prioritario'!$F10,"") | T9: =IF('Hitos del Enfoque Prioritario'!$B10=5,'Hitos del Enfoque Prioritario'!$F10,"") | U9: =IF('Hitos del Enfoque Prioritario'!$B10=6,'Hitos del Enfoque Prioritario'!$F10,"") | V9: =IF(AND('Hitos del Enfoque Prioritario'!C10='Data Validation'!$A$2,'Hitos del Enfoque Prioritario'!F10=""),"CORRECT",IF('Hitos del Enfoque Prioritario'!C10='Data Validation'!$A$3,"CORRECT",IF('Hitos del Enfoque Prioritario'!B10=1,"ERROR 1",'Data Validation'!$A$4))) -> ERROR 1 | W9: =IF(AND('Hitos del Enfoque Prioritario'!C10='Data Validation'!$A$2,'Hitos del Enfoque Prioritario'!F10=""),"CORRECT",IF('Hitos del Enfoque Prioritario'!C10='Data Validation'!$A$3,"CORRECT",IF('Hitos del Enfoque Prioritario'!B10=2,"ERROR 1",'Data Validation'!$A$4))) -> N/A | X9: =IF(AND('Hitos del Enfoque Prioritario'!C10='Data Validation'!$A$2,'Hitos del Enfoque Prioritario'!F10=""),"CORRECT",IF('Hitos del Enfoque Prioritario'!C10='Data Validation'!$A$3,"CORRECT",IF('Hitos del Enfoque Prioritario'!B10=3,"ERROR 1",'Data Validation'!$A$4))) -> N/A | Y9: =IF(AND('Hitos del Enfoque Prioritario'!C10='Data Validation'!$A$2,'Hitos del Enfoque Prioritario'!F10=""),"CORRECT",IF('Hitos del Enfoque Prioritario'!C10='Data Validation'!$A$3,"CORRECT",IF('Hitos del Enfoque Prioritario'!B10=4,"ERROR 1",'Data Validation'!$A$4))) -> N/A | Z9: =IF(AND('Hitos del Enfoque Prioritario'!C10='Data Validation'!$A$2,'Hitos del Enfoque Prioritario'!F10=""),"CORRECT",IF('Hitos del Enfoque Prioritario'!C10='Data Validation'!$A$3,"CORRECT",IF('Hitos del Enfoque Prioritario'!B10=5,"ERROR 1",'Data Validation'!$A$4))) -> N/A | AA9: =IF(AND('Hitos del Enfoque Prioritario'!C10='Data Validation'!$A$2,'Hitos del Enfoque Prioritario'!F10=""),"CORRECT",IF('Hitos del Enfoque Prioritario'!C10='Data Validation'!$A$3,"CORRECT",IF('Hitos del Enfoque Prioritario'!B10=6,"ERROR 1",'Data Validation'!$A$4))) -> N/A | AB9: =IF(AND('Hitos del Enfoque Prioritario'!C10='Data Validation'!$A$3,'Hitos del Enfoque Prioritario'!F10=""),IF('Hitos del Enfoque Prioritario'!B10=1,"ERROR 2",'Data Validation'!$A$4),"CORRECT") -> CORRECT | AC9: =IF(AND('Hitos del Enfoque Prioritario'!C10='Data Validation'!$A$3,'Hitos del Enfoque Prioritario'!F10=""),IF('Hitos del Enfoque Prioritario'!B10=2,"ERROR 2",'Data Validation'!$A$4),"CORRECT") -> CORRECT | AD9: =IF(AND('Hitos del Enfoque Prioritario'!C10='Data Validation'!$A$3,'Hitos del Enfoque Prioritario'!F10=""),IF('Hitos del Enfoque Prioritario'!B10=3,"ERROR 2",'Data Validation'!$A$4),"CORRECT") -> CORRECT | AE9: =IF(AND('Hitos del Enfoque Prioritario'!C10='Data Validation'!$A$3,'Hitos del Enfoque Prioritario'!F10=""),IF('Hitos del Enfoque Prioritario'!B10=4,"ERROR 2",'Data Validation'!$A$4),"CORRECT") -> CORRECT | AF9: =IF(AND('Hitos del Enfoque Prioritario'!C10='Data Validation'!$A$3,'Hitos del Enfoque Prioritario'!F10=""),IF('Hitos del Enfoque Prioritario'!B10=5,"ERROR 2",'Data Validation'!$A$4),"CORRECT") -> CORRECT | AG9: =IF(AND('Hitos del Enfoque Prioritario'!C10='Data Validation'!$A$3,'Hitos del Enfoque Prioritario'!F10=""),IF('Hitos del Enfoque Prioritario'!B10=6,"ERROR 2",'Data Validation'!$A$4),"CORRECT") -> CORRECT
A10: =COUNTIFS('Hitos del Enfoque Prioritario'!B11,"1",'Hitos del Enfoque Prioritario'!C11,'Data Validation'!$A$2) -> 0 | B10: =COUNTIFS('Hitos del Enfoque Prioritario'!B11,"2",'Hitos del Enfoque Prioritario'!C11,'Data Validation'!$A$2) -> 0 | C10: =COUNTIFS('Hitos del Enfoque Prioritario'!B11,"3",'Hitos del Enfoque Prioritario'!C11,'Data Validation'!$A$2) -> 0 | D10: =COUNTIFS('Hitos del Enfoque Prioritario'!B11,"4",'Hitos del Enfoque Prioritario'!C11,'Data Validation'!$A$2) -> 0 | E10: =COUNTIFS('Hitos del Enfoque Prioritario'!B11,"5",'Hitos del Enfoque Prioritario'!C11,'Data Validation'!$A$2) -> 0 | F10: =COUNTIFS('Hitos del Enfoque Prioritario'!B11,"6",'Hitos del Enfoque Prioritario'!C11,'Data Validation'!$A$2) -> 0 | G10: =SUM(A10:F10) -> 0 | H10: =COUNTIFS('Hitos del Enfoque Prioritario'!B11,"1",'Hitos del Enfoque Prioritario'!C11,'Data Validation'!$A$4) -> 0 | I10: =COUNTIFS('Hitos del Enfoque Prioritario'!B11,"2",'Hitos del Enfoque Prioritario'!C11,'Data Validation'!$A$4) -> 0 | J10: =COUNTIFS('Hitos del Enfoque Prioritario'!B11,"3",'Hitos del Enfoque Prioritario'!C11,'Data Validation'!$A$4) -> 0 | K10: =COUNTIFS('Hitos del Enfoque Prioritario'!B11,"4",'Hitos del Enfoque Prioritario'!C11,'Data Validation'!$A$4) -> 0 | L10: =COUNTIFS('Hitos del Enfoque Prioritario'!B11,"5",'Hitos del Enfoque Prioritario'!C11,'Data Validation'!$A$4) -> 0 | M10: =COUNTIFS('Hitos del Enfoque Prioritario'!B11,"6",'Hitos del Enfoque Prioritario'!C11,'Data Validation'!$A$4) -> 0 | N10: =SUM(H10:M10) -> 0 | P10: =IF('Hitos del Enfoque Prioritario'!$B11=1,'Hitos del Enfoque Prioritario'!$F11,"") -> 0 | Q10: =IF('Hitos del Enfoque Prioritario'!$B11=2,'Hitos del Enfoque Prioritario'!$F11,"") | R10: =IF('Hitos del Enfoque Prioritario'!$B11=3,'Hitos del Enfoque Prioritario'!$F11,"") | S10: =IF('Hitos del Enfoque Prioritario'!$B11=4,'Hitos del Enfoque Prioritario'!$F11,"") | T10: =IF('Hitos del Enfoque Prioritario'!$B11=5,'Hitos del Enfoque Prioritario'!$F11,"") | U10: =IF('Hitos del Enfoque Prioritario'!$B11=6,'Hitos del Enfoque Prioritario'!$F11,"") | V10: =IF(AND('Hitos del Enfoque Prioritario'!C11='Data Validation'!$A$2,'Hitos del Enfoque Prioritario'!F11=""),"CORRECT",IF('Hitos del Enfoque Prioritario'!C11='Data Validation'!$A$3,"CORRECT",IF('Hitos del Enfoque Prioritario'!B11=1,"ERROR 1",'Data Validation'!$A$4))) -> ERROR 1 | W10: =IF(AND('Hitos del Enfoque Prioritario'!C11='Data Validation'!$A$2,'Hitos del Enfoque Prioritario'!F11=""),"CORRECT",IF('Hitos del Enfoque Prioritario'!C11='Data Validation'!$A$3,"CORRECT",IF('Hitos del Enfoque Prioritario'!B11=2,"ERROR 1",'Data Validation'!$A$4))) -> N/A | X10: =IF(AND('Hitos del Enfoque Prioritario'!C11='Data Validation'!$A$2,'Hitos del Enfoque Prioritario'!F11=""),"CORRECT",IF('Hitos del Enfoque Prioritario'!C11='Data Validation'!$A$3,"CORRECT",IF('Hitos del Enfoque Prioritario'!B11=3,"ERROR 1",'Data Validation'!$A$4))) -> N/A | Y10: =IF(AND('Hitos del Enfoque Prioritario'!C11='Data Validation'!$A$2,'Hitos del Enfoque Prioritario'!F11=""),"CORRECT",IF('Hitos del Enfoque Prioritario'!C11='Data Validation'!$A$3,"CORRECT",IF('Hitos del Enfoque Prioritario'!B11=4,"ERROR 1",'Data Validation'!$A$4))) -> N/A | Z10: =IF(AND('Hitos del Enfoque Prioritario'!C11='Data Validation'!$A$2,'Hitos del Enfoque Prioritario'!F11=""),"CORRECT",IF('Hitos del Enfoque Prioritario'!C11='Data Validation'!$A$3,"CORRECT",IF('Hitos del Enfoque Prioritario'!B11=5,"ERROR 1",'Data Validation'!$A$4))) -> N/A | AA10: =IF(AND('Hitos del Enfoque Prioritario'!C11='Data Validation'!$A$2,'Hitos del Enfoque Prioritario'!F11=""),"CORRECT",IF('Hitos del Enfoque Prioritario'!C11='Data Validation'!$A$3,"CORRECT",IF('Hitos del Enfoque Prioritario'!B11=6,"ERROR 1",'Data Validation'!$A$4))) -> N/A | AB10: =IF(AND('Hitos del Enfoque Prioritario'!C11='Data Validation'!$A$3,'Hitos del Enfoque Prioritario'!F11=""),IF('Hitos del Enfoque Prioritario'!B11=1,"ERROR 2",'Data Validation'!$A$4),"CORRECT") -> CORRECT | AC10: =IF(AND('Hitos del Enfoque Prioritario'!C11='Data Validation'!$A$3,'Hitos del Enfoque Prioritario'!F11=""),IF('Hitos del Enfoque Prioritario'!B11=2,"ERROR 2",'Data Validation'!$A$4),"CORRECT") -> CORRECT | AD10: =IF(AND('Hitos del Enfoque Prioritario'!C11='Data Validation'!$A$3,'Hitos del Enfoque Prioritario'!F11=""),IF('Hitos del Enfoque Prioritario'!B11=3,"ERROR 2",'Data Validation'!$A$4),"CORRECT") -> CORRECT | AE10: =IF(AND('Hitos del Enfoque Prioritario'!C11='Data Validation'!$A$3,'Hitos del Enfoque Prioritario'!F11=""),IF('Hitos del Enfoque Prioritario'!B11=4,"ERROR 2",'Data Validation'!$A$4),"CORRECT") -> CORRECT | AF10: =IF(AND('Hitos del Enfoque Prioritario'!C11='Data Validation'!$A$3,'Hitos del Enfoque Prioritario'!F11=""),IF('Hitos del Enfoque Prioritario'!B11=5,"ERROR 2",'Data Validation'!$A$4),"CORRECT") -> CORRECT | AG10: =IF(AND('Hitos del Enfoque Prioritario'!C11='Data Validation'!$A$3,'Hitos del Enfoque Prioritario'!F11=""),IF('Hitos del Enfoque Prioritario'!B11=6,"ERROR 2",'Data Validation'!$A$4),"CORRECT") -> CORRECT
